<?xml version="1.0"?>
<robot name="3R_arm">

  <!-- Materiali -->
  <material name="red"><color rgba="1 0 0 1"/></material>
  <material name="green"><color rgba="0 1 0 1"/></material>
  <material name="blue"><color rgba="0 0 1 1"/></material>

  <!-- Base link -->
  <link name="base_link"/>

  <!-- Link 1 -->
  <link name="link1">
    <visual>
      <geometry><cylinder length="1.0" radius="0.02"/></geometry>
      <origin xyz="0 0 0.5" rpy="0 0 0"/>
      <material name="red"/>
    </visual>
  </link>

  <!-- Link 2 -->
  <link name="link2">
    <visual>
      <geometry><cylinder length="0.5" radius="0.02"/></geometry>
      <origin xyz="0.25 0 0" rpy="0 1.5708 0"/>
      <material name="green"/>
    </visual>
  </link>

  <!-- Link 3 -->
  <link name="link3">
    <visual>
      <geometry><cylinder length="0.5" radius="0.02"/></geometry>
      <origin xyz="0.25 0 0" rpy="0 1.5708 0"/>
      <material name="blue"/>
    </visual>
  </link>

  <!-- Joint 1 -->
  <joint name="joint1" type="revolute">
    <parent link="base_link"/>
    <child link="link1"/>
    <origin xyz="0 0 0" rpy="0 0 0"/>
    <axis xyz="0 0 1"/>
    <limit lower="-3.1416" upper="3.1416" effort="10.0" velocity="1.0"/>
  </joint>

  <!-- Joint 2 -->
  <joint name="joint2" type="revolute">
    <parent link="link1"/>
    <child link="link2"/>
    <origin xyz="0 0 1.0" rpy="1.5708 0 0"/>
    <axis xyz="0 0 1"/>
    <limit lower="-3.1416" upper="3.1416" effort="10.0" velocity="1.0"/>
  </joint>

  <!-- Joint 3 -->
  <joint name="joint3" type="revolute">
    <parent link="link2"/>
    <child link="link3"/>
    <origin xyz="0.5 0 0" rpy="0 0 0"/>
    <axis xyz="0 0 1.0"/>
    <limit lower="-3.1416" upper="3.1416" effort="10.0" velocity="1.0"/>
  </joint>

</robot>
